<?xml version="1.0" ?>
<!-- =================================================================================== -->
<!-- |    This document was autogenerated by xacro from sisbot.xacro                   | -->
<!-- |    EDITING THIS FILE BY HAND IS NOT RECOMMENDED                                 | -->
<!-- =================================================================================== -->
<robot name="ur5_robotiq_140" xmlns:xacro="http://ros.org/wiki/xacro">
  <!--################################################
  ########              arm                    #######
  ####################################################-->

  <link name="base_link">
    <visual>
      <geometry>
        <mesh filename="../meshes/ur5/visual/base.obj"/>
      </geometry>
      <material name="LightGrey">
        <color rgba="0.7 0.7 0.7 1.0"/>
      </material>
    </visual>
    <collision>
      <geometry>
        <mesh filename="../meshes/ur5/collision/base.stl"/>
      </geometry>
    </collision>
    <inertial>
      <mass value="4.0"/>
      <origin rpy="0 0 0" xyz="0.0 0.0 0.0"/>
      <inertia ixx="0.00443333156" ixy="0.0" ixz="0.0" iyy="0.00443333156" iyz="0.0" izz="0.0072"/>
    </inertial>
  </link>

  <joint name="shoulder_pan_joint" type="revolute">
    <parent link="base_link"/>
    <child link="shoulder_link"/>
    <origin rpy="0.0 0.0 0.0" xyz="0.0 0.0 0.089159"/>
    <axis xyz="0 0 1"/>
    <limit effort="150.0" lower="-3.14159265359" upper="3.14159265359" velocity="3.15"/>
    <dynamics damping="0.0" friction="0.0"/>
  </joint>
  <link name="shoulder_link">
    <visual>
      <geometry>
        <mesh filename="../meshes/ur5/visual/shoulder.obj"/>
      </geometry>
      <material name="DarkGray">
        <color rgba="0.5 0.5 0.5 1.0"/>
      </material>
    </visual>
    <collision>
      <geometry>
        <mesh filename="../meshes/ur5/collision/shoulder.stl"/>
      </geometry>
    </collision>
    <inertial>
      <mass value="3.7"/>
      <origin rpy="0 0 0" xyz="0.0 0.0 0.0"/>
      <inertia ixx="0.010267495893" ixy="0.0" ixz="0.0" iyy="0.010267495893" iyz="0.0" izz="0.00666"/>
    </inertial>
  </link>
  <joint name="shoulder_lift_joint" type="revolute">
    <parent link="shoulder_link"/>
    <child link="upper_arm_link"/>
    <origin rpy="0.0 1.57079632679 0.0" xyz="0.0 0.13585 0.0"/>
    <axis xyz="0 1 0"/>
    <limit effort="150.0" lower="-3.14159265359" upper="3.14159265359" velocity="3.15"/>
    <dynamics damping="0.0" friction="0.0"/>
  </joint>
  <link name="upper_arm_link">
    <visual>
      <geometry>
        <mesh filename="../meshes/ur5/visual/upperarm.obj"/>
      </geometry>
      <material name="LightGrey">
        <color rgba="0.7 0.7 0.7 1.0"/>
      </material>
    </visual>
    <collision>
      <geometry>
        <mesh filename="../meshes/ur5/collision/upperarm.stl"/>
      </geometry>
    </collision>
    <inertial>
      <mass value="8.393"/>
      <origin rpy="0 0 0" xyz="0.0 0.0 0.28"/>
      <inertia ixx="0.22689067591" ixy="0.0" ixz="0.0" iyy="0.22689067591" iyz="0.0" izz="0.0151074"/>
    </inertial>
  </link>
  <joint name="elbow_joint" type="revolute">
    <parent link="upper_arm_link"/>
    <child link="forearm_link"/>
    <origin rpy="0.0 0.0 0.0" xyz="0.0 -0.1197 0.425"/>
    <axis xyz="0 1 0"/>
    <limit effort="150.0" lower="-3.14159265359" upper="3.14159265359" velocity="3.15"/>
    <dynamics damping="0.0" friction="0.0"/>
  </joint>
  <link name="forearm_link">
    <visual>
      <geometry>
        <mesh filename="../meshes/ur5/visual/forearm.obj"/>
      </geometry>
      <material name="LightGrey">
        <color rgba="0.7 0.7 0.7 1.0"/>
      </material>
    </visual>
    <collision>
      <geometry>
        <mesh filename="../meshes/ur5/collision/forearm.stl"/>
      </geometry>
    </collision>
    <inertial>
      <mass value="2.275"/>
      <origin rpy="0 0 0" xyz="0.0 0.0 0.25"/>
      <inertia ixx="0.049443313556" ixy="0.0" ixz="0.0" iyy="0.049443313556" iyz="0.0" izz="0.004095"/>
    </inertial>
  </link>
  <joint name="wrist_1_joint" type="revolute">
    <parent link="forearm_link"/>
    <child link="wrist_1_link"/>
    <origin rpy="0.0 1.57079632679 0.0" xyz="0.0 0.0 0.39225"/>
    <axis xyz="0 1 0"/>
    <limit effort="28.0" lower="-3.14159265359" upper="3.14159265359" velocity="3.2"/>
    <dynamics damping="0.0" friction="0.0"/>
  </joint>
  <link name="wrist_1_link">
    <visual>
      <geometry>
        <mesh filename="../meshes/ur5/visual/wrist1.obj"/>
      </geometry>
      <material name="DarkGray">
        <color rgba="0.5 0.5 0.5 1.0"/>
      </material>
    </visual>
    <collision>
      <geometry>
        <mesh filename="../meshes/ur5/collision/wrist1.stl"/>
      </geometry>
    </collision>
    <inertial>
      <mass value="1.219"/>
      <origin rpy="0 0 0" xyz="0.0 0.0 0.0"/>
      <inertia ixx="0.111172755531" ixy="0.0" ixz="0.0" iyy="0.111172755531" iyz="0.0" izz="0.21942"/>
    </inertial>
  </link>
  <joint name="wrist_2_joint" type="revolute">
    <parent link="wrist_1_link"/>
    <child link="wrist_2_link"/>
    <origin rpy="0.0 0.0 0.0" xyz="0.0 0.093 0.0"/>
    <axis xyz="0 0 1"/>
    <limit effort="28.0" lower="-3.14159265359" upper="3.14159265359" velocity="3.2"/>
    <dynamics damping="0.0" friction="0.0"/>
  </joint>
  <link name="wrist_2_link">
    <visual>
      <geometry>
        <mesh filename="../meshes/ur5/visual/wrist2.obj"/>
      </geometry>
      <material name="DarkGray">
        <color rgba="0.5 0.5 0.5 1.0"/>
      </material>
    </visual>
    <collision>
      <geometry>
        <mesh filename="../meshes/ur5/collision/wrist2.stl"/>
      </geometry>
    </collision>
    <inertial>
      <mass value="1.219"/>
      <origin rpy="0 0 0" xyz="0.0 0.0 0.0"/>
      <inertia ixx="0.111172755531" ixy="0.0" ixz="0.0" iyy="0.111172755531" iyz="0.0" izz="0.21942"/>
    </inertial>
  </link>
  <joint name="wrist_3_joint" type="revolute">
    <parent link="wrist_2_link"/>
    <child link="wrist_3_link"/>
    <origin rpy="0.0 0.0 0.0" xyz="0.0 0.0 0.09465"/>
    <axis xyz="0 1 0"/>
    <limit effort="28.0" lower="-3.14159265359" upper="3.14159265359" velocity="3.2"/>
    <dynamics damping="0.0" friction="0.0"/>
  </joint>
  <link name="wrist_3_link">
    <visual>
      <geometry>
        <mesh filename="../meshes/ur5/visual/wrist3.obj"/>
      </geometry>
      <material name="LightGrey">
        <color rgba="0.7 0.7 0.7 1.0"/>
      </material>
    </visual>
    <collision>
      <geometry>
        <mesh filename="../meshes/ur5/collision/wrist3.stl"/>
      </geometry>
    </collision>
    <inertial>
      <mass value="0.1879"/>
      <origin rpy="0 0 0" xyz="0.0 0.0 0.0"/>
      <inertia ixx="0.0171364731454" ixy="0.0" ixz="0.0" iyy="0.0171364731454" iyz="0.0" izz="0.033822"/>
    </inertial>
  </link>
  <joint name="ee_fixed_joint" type="fixed">
    <parent link="wrist_3_link"/>
    <child link="robotiq_85_base_link"/>
    <origin rpy="0.0 0.0 1.57079632679" xyz="0.0 0.0823 0.0"/>
  </joint>


  <!--################################################
  ########              gripper                  #####
  ####################################################-->

  <!-- robot -->
  <link name="end_effector_indicator_link">
    <visual>
      <geometry>
        <box size="0.005 0.005 0.005"/>
      </geometry>
      <material name="Yellow">
        <color rgba="1.0 0.7 0.0 1.0"/>
      </material>
    </visual>
    <inertial>
      <mass value="0.1" />
      <inertia ixx = "0" ixy = "0" ixz = "0"
               iyx = "0" iyy = "0" iyz = "0"
               izx = "0" izy = "0" izz = "0" />
    </inertial>
  </link>

  <joint name="end_effector_fixed_joint" type="fixed">
    <parent link="robotiq_85_base_link"/>
    <child link="end_effector_indicator_link"/>
    <origin xyz="0.137 0 0" />
  </joint>

  <link name="robotiq_85_base_link">
    <visual>
      <geometry>
        <mesh filename="../meshes2/visual/robotiq_85_base_link.dae"/>
      </geometry>
      <material name="Silver">
        <color rgba="0.0 0.0 0.0 1.0"/>
      </material>
    </visual>
    <collision>
      <geometry>
        <mesh filename="../meshes2/collision/robotiq_85_base_link.stl"/>
      </geometry>
    </collision>
    <inertial>
      <mass value="0.636951" />
      <origin xyz="0.0 0.0 0.0" />
      <inertia ixx = "0.000380" ixy = "0.000000" ixz = "0.000000"
           iyx = "0.000000" iyy = "0.001110" iyz = "0.000000"
           izx = "0.000000" izy = "0.000000" izz = "0.001171" />
    </inertial>
  </link>

  <joint name="robotiq_85_left_knuckle_joint" type="revolute">
    <parent link="robotiq_85_base_link"/>
    <child link="robotiq_85_left_knuckle_link"/>
    <axis xyz="0 0 1"/>
    <origin rpy="3.14 0.0 0.0" xyz="0.05490451627 0.03060114443 0.0"/>
    <limit lower="0.0" upper="0.80285" velocity="3.14" effort="1000"/>
  </joint>

  <joint name="robotiq_85_right_knuckle_joint" type="revolute">
    <parent link="robotiq_85_base_link"/>
    <child link="robotiq_85_right_knuckle_link"/>
    <axis xyz="0 0 1"/>
    <origin rpy="0.0 0.0 0.0" xyz="0.05490451627 -0.03060114443 0.0"/>
    <limit lower="-3.14" upper="3.14" velocity="3.14" effort="1000"/>
    <mimic joint="robotiq_85_left_knuckle_joint"/>
  </joint>

  <link name="robotiq_85_left_knuckle_link">
    <visual>
      <geometry>
        <mesh filename="../meshes2/visual/robotiq_85_knuckle_link.dae"/>
      </geometry>
      <material name="Black">
        <color rgba="1.0 1.0 1.0 1.0"/>
      </material>
    </visual>
    <collision>
      <geometry>
        <mesh filename="../meshes2/collision/robotiq_85_knuckle_link.stl"/>
      </geometry>
    </collision>
    <inertial>
      <mass value="0.018491" />
      <origin xyz="0.0 0.0 0.0" />
      <inertia ixx = "0.000009" ixy = "-0.000001" ixz = "0.000000"
           iyx = "-0.000001" iyy = "0.000001" iyz = "0.000000"
           izx = "0.000000" izy = "0.000000" izz = "0.000010" />
    </inertial>
  </link>

  <link name="robotiq_85_right_knuckle_link">
    <visual>
      <geometry>
        <mesh filename="../meshes2/visual/robotiq_85_knuckle_link.dae"/>
      </geometry>
      <material name="Black">
        <color rgba="1.0 1.0 1.0 1.0"/>
      </material>
    </visual>
    <collision>
      <geometry>
        <mesh filename="../meshes2/collision/robotiq_85_knuckle_link.stl"/>
      </geometry>
    </collision>
    <inertial>
      <mass value="0.018491" />
      <origin xyz="0.0 0.0 0.0" />
      <inertia ixx = "0.000009" ixy = "-0.000001" ixz = "0.000000"
           iyx = "-0.000001" iyy = "0.000001" iyz = "0.000000"
           izx = "0.000000" izy = "0.000000" izz = "0.000010" />
    </inertial>
  </link>

  <joint name="robotiq_85_left_finger_joint" type="fixed">
    <parent link="robotiq_85_left_knuckle_link"/>
    <child link="robotiq_85_left_finger_link"/>
    <origin xyz="-0.00408552455 -0.03148604435 0.0" rpy="0 0 0" />
  </joint>

  <joint name="robotiq_85_right_finger_joint" type="fixed">
    <parent link="robotiq_85_right_knuckle_link"/>
    <child link="robotiq_85_right_finger_link"/>
    <origin xyz="-0.00408552455 -0.03148604435 0.0" rpy="0 0 0" />
  </joint>

  <link name="robotiq_85_left_finger_link">
    <visual>
      <geometry>
        <mesh filename="../meshes2/visual/robotiq_85_finger_link.dae"/>
      </geometry>
      <material name="Silver">
        <color rgba="0.3 0.3 0.3 1.0"/>
      </material>
    </visual>
    <collision>
      <geometry>
        <mesh filename="../meshes2/collision/robotiq_85_finger_link.stl"/>
      </geometry>
    </collision>
    <inertial>
      <mass value="0.027309" />
      <origin xyz="0.0 0.0 0.0" />
      <inertia ixx = "0.000003" ixy = "-0.000002" ixz = "0.000000"
           iyx = "-0.000002" iyy = "0.000021" iyz = "0.000000"
           izx = "0.000000" izy = "0.000000" izz = "0.000020" />
    </inertial>
  </link>

  <link name="robotiq_85_right_finger_link">
    <visual>
      <geometry>
        <mesh filename="../meshes2/visual/robotiq_85_finger_link.dae"/>
      </geometry>
      <material name="Silver">
        <color rgba="0.3 0.3 0.3 1.0"/>
      </material>
    </visual>
    <collision>
      <geometry>
        <mesh filename="../meshes2/collision/robotiq_85_finger_link.stl"/>
      </geometry>
    </collision>
    <inertial>
      <mass value="0.027309" />
      <origin xyz="0.0 0.0 0.0" />
      <inertia ixx = "0.000003" ixy = "-0.000002" ixz = "0.000000"
           iyx = "-0.000002" iyy = "0.000021" iyz = "0.000000"
           izx = "0.000000" izy = "0.000000" izz = "0.000020" />
    </inertial>
  </link>

  <joint name="robotiq_85_left_inner_knuckle_joint" type="revolute">
    <parent link="robotiq_85_base_link"/>
    <child link="robotiq_85_left_inner_knuckle_link"/>
    <axis xyz="0 0 1"/>
    <origin xyz="0.06142 0.0127 0" rpy="3.14 0.0 0.0" />
    <limit lower="-3.14" upper="3.14" velocity="3.14" effort="0.1"/>
    <mimic joint="robotiq_85_left_knuckle_joint" offset="0"/>
  </joint>

  <joint name="robotiq_85_right_inner_knuckle_joint" type="revolute">
    <parent link="robotiq_85_base_link"/>
    <child link="robotiq_85_right_inner_knuckle_link"/>
    <axis xyz="0 0 1"/>
    <origin xyz="0.06142 -0.0127 0" rpy="0 0 0"/>
    <limit lower="-3.14" upper="3.14" velocity="3.14" effort="0.1"/>
    <mimic joint="robotiq_85_left_knuckle_joint" offset="0"/>
  </joint>

  <link name="robotiq_85_left_inner_knuckle_link">
    <visual>
      <geometry>
        <mesh filename="../meshes2/visual/robotiq_85_inner_knuckle_link.dae"/>
      </geometry>
      <material name="Black">
        <color rgba="1.0 1.0 1.0 1.0"/>
      </material>
    </visual>
    <collision>
      <geometry>
        <mesh filename="../meshes2/collision/robotiq_85_inner_knuckle_link.stl"/>
      </geometry>
    </collision>
    <inertial>
      <mass value="0.029951" />
      <origin xyz="0.0 0.0 0.0" />
      <inertia ixx = "0.000039" ixy = "0.000000" ixz = "0.000000"
           iyx = "0.000000" iyy = "0.000005" iyz = "0.000000"
           izx = "0.000000" izy = "0.000000" izz = "0.000035" />
    </inertial>
  </link>
  <link name="robotiq_85_right_inner_knuckle_link">
    <visual>
      <geometry>
        <mesh filename="../meshes2/visual/robotiq_85_inner_knuckle_link.dae"/>
      </geometry>
      <material name="Black">
        <color rgba="1.0 1.0 1.0 1.0"/>
      </material>
    </visual>
    <collision>
      <geometry>
        <mesh filename="../meshes2/collision/robotiq_85_inner_knuckle_link.stl"/>
      </geometry>
    </collision>
    <inertial>
      <mass value="0.029951" />
      <origin xyz="0.0 0.0 0.0" />
      <inertia ixx = "0.000039" ixy = "0.000000" ixz = "0.000000"
           iyx = "0.000000" iyy = "0.000005" iyz = "0.000000"
           izx = "0.000000" izy = "0.000000" izz = "0.000035" />
    </inertial>
  </link>

  <joint name="robotiq_85_left_finger_tip_joint" type="revolute">
    <parent link="robotiq_85_left_inner_knuckle_link"/>
    <child link="robotiq_85_left_finger_tip_link"/>
    <axis xyz="0 0 1"/>
    <origin xyz="0.04303959807 -0.03759940821 0.0" rpy="0.0 0.0 0.0"/>
    <limit lower="-3.14" upper="3.14" velocity="3.14" effort="0.1"/>
    <mimic joint="robotiq_85_left_knuckle_joint" multiplier="-1"/>
  </joint>

  <joint name="robotiq_85_right_finger_tip_joint" type="revolute">
    <parent link="robotiq_85_right_inner_knuckle_link"/>
    <child link="robotiq_85_right_finger_tip_link"/>
    <axis xyz="0 0 1"/>
    <origin rpy="0.0 0.0 0.0" xyz="0.04303959807 -0.03759940821  0.0"/>
    <limit lower="-3.14" upper="3.14" velocity="3.14" effort="0.1"/>
    <mimic joint="robotiq_85_left_knuckle_joint" multiplier="-1"/>
  </joint>


  <link name="robotiq_85_left_finger_tip_link">
    <visual>
      <geometry>
        <mesh filename="../meshes2/visual/robotiq_85_finger_tip_link.dae"/>
      </geometry>
      <material name="Silver">
        <color rgba="0.3 0.3 0.3 1.0"/>
      </material>
    </visual>
    <collision>
      <geometry>
        <mesh filename="../meshes2/collision/robotiq_85_finger_tip_link.stl"/>
      </geometry>
    </collision>
    <inertial>
      <mass value="0.019555" />
      <origin xyz="0.0 0.0 0.0" />
      <inertia ixx = "0.000002" ixy = "0.000000" ixz = "0.000000"
           iyx = "0.000000" iyy = "0.000005" iyz = "0.000000"
           izx = "0.000000" izy = "0.000000" izz = "0.000006" />
    </inertial>
  </link>

  <link name="robotiq_85_right_finger_tip_link">
    <visual>
      <geometry>
        <mesh filename="../meshes/visual/robotiq_85_finger_tip_link.dae"/>
      </geometry>
      <material name="Silver">
        <color rgba="0.3 0.3 0.3 1.0"/>
      </material>
    </visual>
    <collision>
      <geometry>
        <mesh filename="../meshes/collision/robotiq_85_finger_tip_link.stl"/>
      </geometry>
    </collision>
    <inertial>
      <mass value="0.019555" />
      <origin xyz="0.0 0.0 0.0" />
      <inertia ixx = "0.000002" ixy = "0.000000" ixz = "0.000000"
           iyx = "0.000000" iyy = "0.000005" iyz = "0.000000"
           izx = "0.000000" izy = "0.000000" izz = "0.000006" />
    </inertial>
  </link>


<!--################################################
  ########          connect model                #####
  ####################################################-->

  <link name="world"/>
  <!-- connect gripper to arm -->
<!--   <joint name="arm_gripper_joint" type="fixed">
    <parent link="ee_link"/>
    <child link="robotiq_85_base_link"/>
    <origin rpy="0.0 0.0 0.0" xyz="0.0 0.0 0.0"/>
  </joint> -->

  <!-- connect arm to world -->
  <joint name="world_arm_joint" type="fixed">
    <parent link="world"/>
    <child link="base_link"/>
    <origin rpy="0.0 0.0 0" xyz="0 0 0.78"/>
  </joint>


</robot>

